WARNING 2025-01-05 16:52:27,136 log Not Found: /favicon.ico
WARNING 2025-01-05 16:53:17,980 log Not Found: /favicon.ico
WARNING 2025-01-05 17:08:18,204 log Not Found: /favicon.ico
WARNING 2025-01-05 17:15:59,177 log Not Found: /favicon.ico
ERROR 2025-01-05 17:16:01,532 log Internal Server Error: /resource/
Traceback (most recent call last):
  File "/home/kali/CyberTea App/cyberteaenv/lib/python3.11/site-packages/django/template/backends/django.py", line 107, in render
    return self.template.render(context)
           ^^^^^^^^^^^^^^^^^^^^^^^^^^^^^
  File "/home/kali/CyberTea App/cyberteaenv/lib/python3.11/site-packages/django/template/base.py", line 171, in render
    return self._render(context)
           ^^^^^^^^^^^^^^^^^^^^^
  File "/home/kali/CyberTea App/cyberteaenv/lib/python3.11/site-packages/django/template/base.py", line 163, in _render
    return self.nodelist.render(context)
           ^^^^^^^^^^^^^^^^^^^^^^^^^^^^^
  File "/home/kali/CyberTea App/cyberteaenv/lib/python3.11/site-packages/django/template/base.py", line 1008, in render
    return SafeString("".join([node.render_annotated(context) for node in self]))
                              ^^^^^^^^^^^^^^^^^^^^^^^^^^^^^^^^^^^^^^^^^^^^^^^^^
  File "/home/kali/CyberTea App/cyberteaenv/lib/python3.11/site-packages/django/template/base.py", line 1008, in <listcomp>
    return SafeString("".join([node.render_annotated(context) for node in self]))
                               ^^^^^^^^^^^^^^^^^^^^^^^^^^^^^^
  File "/home/kali/CyberTea App/cyberteaenv/lib/python3.11/site-packages/django/template/base.py", line 969, in render_annotated
    return self.render(context)
           ^^^^^^^^^^^^^^^^^^^^
  File "/home/kali/CyberTea App/cyberteaenv/lib/python3.11/site-packages/django/template/loader_tags.py", line 134, in render
    compiled_parent = self.get_parent(context)
                      ^^^^^^^^^^^^^^^^^^^^^^^^
  File "/home/kali/CyberTea App/cyberteaenv/lib/python3.11/site-packages/django/template/loader_tags.py", line 131, in get_parent
    return self.find_template(parent, context)
           ^^^^^^^^^^^^^^^^^^^^^^^^^^^^^^^^^^^
  File "/home/kali/CyberTea App/cyberteaenv/lib/python3.11/site-packages/django/template/loader_tags.py", line 109, in find_template
    template, origin = context.template.engine.find_template(
                       ^^^^^^^^^^^^^^^^^^^^^^^^^^^^^^^^^^^^^^
  File "/home/kali/CyberTea App/cyberteaenv/lib/python3.11/site-packages/django/template/engine.py", line 163, in find_template
    raise TemplateDoesNotExist(name, tried=tried)
django.template.exceptions.TemplateDoesNotExist: resources/base.html

The above exception was the direct cause of the following exception:

Traceback (most recent call last):
  File "/home/kali/CyberTea App/cyberteaenv/lib/python3.11/site-packages/django/core/handlers/exception.py", line 55, in inner
    response = get_response(request)
               ^^^^^^^^^^^^^^^^^^^^^
  File "/home/kali/CyberTea App/cyberteaenv/lib/python3.11/site-packages/django/core/handlers/base.py", line 197, in _get_response
    response = wrapped_callback(request, *callback_args, **callback_kwargs)
               ^^^^^^^^^^^^^^^^^^^^^^^^^^^^^^^^^^^^^^^^^^^^^^^^^^^^^^^^^^^^
  File "/home/kali/CyberTea App/cybertea_project/cybertea_app/views.py", line 179, in resource
    return render(request, 'resources/resource.html', {'about': about})
           ^^^^^^^^^^^^^^^^^^^^^^^^^^^^^^^^^^^^^^^^^^^^^^^^^^^^^^^^^^^^
  File "/home/kali/CyberTea App/cyberteaenv/lib/python3.11/site-packages/django/shortcuts.py", line 25, in render
    content = loader.render_to_string(template_name, context, request, using=using)
              ^^^^^^^^^^^^^^^^^^^^^^^^^^^^^^^^^^^^^^^^^^^^^^^^^^^^^^^^^^^^^^^^^^^^^
  File "/home/kali/CyberTea App/cyberteaenv/lib/python3.11/site-packages/django/template/loader.py", line 62, in render_to_string
    return template.render(context, request)
           ^^^^^^^^^^^^^^^^^^^^^^^^^^^^^^^^^
  File "/home/kali/CyberTea App/cyberteaenv/lib/python3.11/site-packages/django/template/backends/django.py", line 109, in render
    reraise(exc, self.backend)
  File "/home/kali/CyberTea App/cyberteaenv/lib/python3.11/site-packages/django/template/backends/django.py", line 130, in reraise
    raise new from exc
django.template.exceptions.TemplateDoesNotExist: resources/base.html
WARNING 2025-01-05 17:22:58,762 log Not Found: /favicon.ico
WARNING 2025-01-05 17:23:43,295 log Not Found: /favicon.ico
WARNING 2025-01-05 17:24:16,469 log Not Found: /favicon.ico
WARNING 2025-01-05 17:30:47,934 log Not Found: /favicon.ico
WARNING 2025-01-05 17:39:54,591 log Not Found: /favicon.ico
WARNING 2025-01-05 17:45:10,256 log Not Found: /favicon.ico
WARNING 2025-01-05 17:45:17,987 log Not Found: /favicon.ico
WARNING 2025-01-05 17:46:52,643 log Not Found: /favicon.ico
WARNING 2025-01-05 17:47:42,802 log Not Found: /favicon.ico
WARNING 2025-01-05 17:59:34,238 log Not Found: /favicon.ico
ERROR 2025-01-05 18:10:00,914 log Internal Server Error: /forums/
Traceback (most recent call last):
  File "/home/kali/CyberTea App/cyberteaenv/lib/python3.11/site-packages/django/core/handlers/exception.py", line 55, in inner
    response = get_response(request)
               ^^^^^^^^^^^^^^^^^^^^^
  File "/home/kali/CyberTea App/cyberteaenv/lib/python3.11/site-packages/django/core/handlers/base.py", line 197, in _get_response
    response = wrapped_callback(request, *callback_args, **callback_kwargs)
               ^^^^^^^^^^^^^^^^^^^^^^^^^^^^^^^^^^^^^^^^^^^^^^^^^^^^^^^^^^^^
  File "/home/kali/CyberTea App/cybertea_project/cybertea_app/views.py", line 113, in forums
    return render(request, "cyberevents/forums.html", context)
           ^^^^^^^^^^^^^^^^^^^^^^^^^^^^^^^^^^^^^^^^^^^^^^^^^^^
  File "/home/kali/CyberTea App/cyberteaenv/lib/python3.11/site-packages/django/shortcuts.py", line 25, in render
    content = loader.render_to_string(template_name, context, request, using=using)
              ^^^^^^^^^^^^^^^^^^^^^^^^^^^^^^^^^^^^^^^^^^^^^^^^^^^^^^^^^^^^^^^^^^^^^
  File "/home/kali/CyberTea App/cyberteaenv/lib/python3.11/site-packages/django/template/loader.py", line 62, in render_to_string
    return template.render(context, request)
           ^^^^^^^^^^^^^^^^^^^^^^^^^^^^^^^^^
  File "/home/kali/CyberTea App/cyberteaenv/lib/python3.11/site-packages/django/template/backends/django.py", line 107, in render
    return self.template.render(context)
           ^^^^^^^^^^^^^^^^^^^^^^^^^^^^^
  File "/home/kali/CyberTea App/cyberteaenv/lib/python3.11/site-packages/django/template/base.py", line 171, in render
    return self._render(context)
           ^^^^^^^^^^^^^^^^^^^^^
  File "/home/kali/CyberTea App/cyberteaenv/lib/python3.11/site-packages/django/template/base.py", line 163, in _render
    return self.nodelist.render(context)
           ^^^^^^^^^^^^^^^^^^^^^^^^^^^^^
  File "/home/kali/CyberTea App/cyberteaenv/lib/python3.11/site-packages/django/template/base.py", line 1008, in render
    return SafeString("".join([node.render_annotated(context) for node in self]))
                              ^^^^^^^^^^^^^^^^^^^^^^^^^^^^^^^^^^^^^^^^^^^^^^^^^
  File "/home/kali/CyberTea App/cyberteaenv/lib/python3.11/site-packages/django/template/base.py", line 1008, in <listcomp>
    return SafeString("".join([node.render_annotated(context) for node in self]))
                               ^^^^^^^^^^^^^^^^^^^^^^^^^^^^^^
  File "/home/kali/CyberTea App/cyberteaenv/lib/python3.11/site-packages/django/template/base.py", line 969, in render_annotated
    return self.render(context)
           ^^^^^^^^^^^^^^^^^^^^
  File "/home/kali/CyberTea App/cyberteaenv/lib/python3.11/site-packages/django/template/loader_tags.py", line 159, in render
    return compiled_parent._render(context)
           ^^^^^^^^^^^^^^^^^^^^^^^^^^^^^^^^
  File "/home/kali/CyberTea App/cyberteaenv/lib/python3.11/site-packages/django/template/base.py", line 163, in _render
    return self.nodelist.render(context)
           ^^^^^^^^^^^^^^^^^^^^^^^^^^^^^
  File "/home/kali/CyberTea App/cyberteaenv/lib/python3.11/site-packages/django/template/base.py", line 1008, in render
    return SafeString("".join([node.render_annotated(context) for node in self]))
                              ^^^^^^^^^^^^^^^^^^^^^^^^^^^^^^^^^^^^^^^^^^^^^^^^^
  File "/home/kali/CyberTea App/cyberteaenv/lib/python3.11/site-packages/django/template/base.py", line 1008, in <listcomp>
    return SafeString("".join([node.render_annotated(context) for node in self]))
                               ^^^^^^^^^^^^^^^^^^^^^^^^^^^^^^
  File "/home/kali/CyberTea App/cyberteaenv/lib/python3.11/site-packages/django/template/base.py", line 969, in render_annotated
    return self.render(context)
           ^^^^^^^^^^^^^^^^^^^^
  File "/home/kali/CyberTea App/cyberteaenv/lib/python3.11/site-packages/django/template/loader_tags.py", line 65, in render
    result = block.nodelist.render(context)
             ^^^^^^^^^^^^^^^^^^^^^^^^^^^^^^
  File "/home/kali/CyberTea App/cyberteaenv/lib/python3.11/site-packages/django/template/base.py", line 1008, in render
    return SafeString("".join([node.render_annotated(context) for node in self]))
                              ^^^^^^^^^^^^^^^^^^^^^^^^^^^^^^^^^^^^^^^^^^^^^^^^^
  File "/home/kali/CyberTea App/cyberteaenv/lib/python3.11/site-packages/django/template/base.py", line 1008, in <listcomp>
    return SafeString("".join([node.render_annotated(context) for node in self]))
                               ^^^^^^^^^^^^^^^^^^^^^^^^^^^^^^
  File "/home/kali/CyberTea App/cyberteaenv/lib/python3.11/site-packages/django/template/base.py", line 969, in render_annotated
    return self.render(context)
           ^^^^^^^^^^^^^^^^^^^^
  File "/home/kali/CyberTea App/cyberteaenv/lib/python3.11/site-packages/django/template/defaulttags.py", line 480, in render
    url = reverse(view_name, args=args, kwargs=kwargs, current_app=current_app)
          ^^^^^^^^^^^^^^^^^^^^^^^^^^^^^^^^^^^^^^^^^^^^^^^^^^^^^^^^^^^^^^^^^^^^^
  File "/home/kali/CyberTea App/cyberteaenv/lib/python3.11/site-packages/django/urls/base.py", line 88, in reverse
    return resolver._reverse_with_prefix(view, prefix, *args, **kwargs)
           ^^^^^^^^^^^^^^^^^^^^^^^^^^^^^^^^^^^^^^^^^^^^^^^^^^^^^^^^^^^^
  File "/home/kali/CyberTea App/cyberteaenv/lib/python3.11/site-packages/django/urls/resolvers.py", line 831, in _reverse_with_prefix
    raise NoReverseMatch(msg)
django.urls.exceptions.NoReverseMatch: Reverse for 'forum_search' not found. 'forum_search' is not a valid view function or pattern name.
WARNING 2025-01-05 18:14:50,233 log Not Found: /favicon.ico
WARNING 2025-01-05 18:22:42,555 log Not Found: /favicon.ico
WARNING 2025-01-05 18:23:38,408 log Not Found: /favicon.ico
WARNING 2025-01-05 18:31:27,131 log Not Found: /favicon.ico
WARNING 2025-01-05 18:36:01,044 log Not Found: /favicon.ico
WARNING 2025-01-05 18:36:57,480 log Not Found: /favicon.ico
WARNING 2025-01-05 18:49:09,970 log Not Found: /favicon.ico
WARNING 2025-01-05 18:49:21,257 log Not Found: /favicon.ico
WARNING 2025-01-05 19:00:46,063 log Not Found: /favicon.ico
WARNING 2025-01-05 19:01:39,692 log Not Found: /favicon.ico
WARNING 2025-01-05 19:01:43,053 log Not Found: /favicon.ico
ERROR 2025-01-05 19:06:13,634 log Internal Server Error: /search/
Traceback (most recent call last):
  File "/home/kali/CyberTea App/cyberteaenv/lib/python3.11/site-packages/django/core/handlers/exception.py", line 55, in inner
    response = get_response(request)
               ^^^^^^^^^^^^^^^^^^^^^
  File "/home/kali/CyberTea App/cyberteaenv/lib/python3.11/site-packages/django/core/handlers/base.py", line 197, in _get_response
    response = wrapped_callback(request, *callback_args, **callback_kwargs)
               ^^^^^^^^^^^^^^^^^^^^^^^^^^^^^^^^^^^^^^^^^^^^^^^^^^^^^^^^^^^^
  File "/home/kali/CyberTea App/cybertea_project/cybertea_app/views.py", line 189, in forum_search
    return render(request, 'cyberevents/forums.html', {
           ^^^^^^^^^^^^^^^^^^^^^^^^^^^^^^^^^^^^^^^^^^^^
  File "/home/kali/CyberTea App/cyberteaenv/lib/python3.11/site-packages/django/shortcuts.py", line 25, in render
    content = loader.render_to_string(template_name, context, request, using=using)
              ^^^^^^^^^^^^^^^^^^^^^^^^^^^^^^^^^^^^^^^^^^^^^^^^^^^^^^^^^^^^^^^^^^^^^
  File "/home/kali/CyberTea App/cyberteaenv/lib/python3.11/site-packages/django/template/loader.py", line 61, in render_to_string
    template = get_template(template_name, using=using)
               ^^^^^^^^^^^^^^^^^^^^^^^^^^^^^^^^^^^^^^^^
  File "/home/kali/CyberTea App/cyberteaenv/lib/python3.11/site-packages/django/template/loader.py", line 15, in get_template
    return engine.get_template(template_name)
           ^^^^^^^^^^^^^^^^^^^^^^^^^^^^^^^^^^
  File "/home/kali/CyberTea App/cyberteaenv/lib/python3.11/site-packages/django/template/backends/django.py", line 79, in get_template
    return Template(self.engine.get_template(template_name), self)
                    ^^^^^^^^^^^^^^^^^^^^^^^^^^^^^^^^^^^^^^^
  File "/home/kali/CyberTea App/cyberteaenv/lib/python3.11/site-packages/django/template/engine.py", line 177, in get_template
    template, origin = self.find_template(template_name)
                       ^^^^^^^^^^^^^^^^^^^^^^^^^^^^^^^^^
  File "/home/kali/CyberTea App/cyberteaenv/lib/python3.11/site-packages/django/template/engine.py", line 159, in find_template
    template = loader.get_template(name, skip=skip)
               ^^^^^^^^^^^^^^^^^^^^^^^^^^^^^^^^^^^^
  File "/home/kali/CyberTea App/cyberteaenv/lib/python3.11/site-packages/django/template/loaders/cached.py", line 57, in get_template
    template = super().get_template(template_name, skip)
               ^^^^^^^^^^^^^^^^^^^^^^^^^^^^^^^^^^^^^^^^^
  File "/home/kali/CyberTea App/cyberteaenv/lib/python3.11/site-packages/django/template/loaders/base.py", line 28, in get_template
    return Template(
           ^^^^^^^^^
  File "/home/kali/CyberTea App/cyberteaenv/lib/python3.11/site-packages/django/template/base.py", line 154, in __init__
    self.nodelist = self.compile_nodelist()
                    ^^^^^^^^^^^^^^^^^^^^^^^
  File "/home/kali/CyberTea App/cyberteaenv/lib/python3.11/site-packages/django/template/base.py", line 196, in compile_nodelist
    nodelist = parser.parse()
               ^^^^^^^^^^^^^^
  File "/home/kali/CyberTea App/cyberteaenv/lib/python3.11/site-packages/django/template/base.py", line 518, in parse
    raise self.error(token, e)
  File "/home/kali/CyberTea App/cyberteaenv/lib/python3.11/site-packages/django/template/base.py", line 516, in parse
    compiled_result = compile_func(self, token)
                      ^^^^^^^^^^^^^^^^^^^^^^^^^
  File "/home/kali/CyberTea App/cyberteaenv/lib/python3.11/site-packages/django/template/loader_tags.py", line 295, in do_extends
    nodelist = parser.parse()
               ^^^^^^^^^^^^^^
  File "/home/kali/CyberTea App/cyberteaenv/lib/python3.11/site-packages/django/template/base.py", line 518, in parse
    raise self.error(token, e)
  File "/home/kali/CyberTea App/cyberteaenv/lib/python3.11/site-packages/django/template/base.py", line 516, in parse
    compiled_result = compile_func(self, token)
                      ^^^^^^^^^^^^^^^^^^^^^^^^^
  File "/home/kali/CyberTea App/cyberteaenv/lib/python3.11/site-packages/django/template/loader_tags.py", line 234, in do_block
    nodelist = parser.parse(("endblock",))
               ^^^^^^^^^^^^^^^^^^^^^^^^^^^
  File "/home/kali/CyberTea App/cyberteaenv/lib/python3.11/site-packages/django/template/base.py", line 518, in parse
    raise self.error(token, e)
  File "/home/kali/CyberTea App/cyberteaenv/lib/python3.11/site-packages/django/template/base.py", line 516, in parse
    compiled_result = compile_func(self, token)
                      ^^^^^^^^^^^^^^^^^^^^^^^^^
  File "/home/kali/CyberTea App/cyberteaenv/lib/python3.11/site-packages/django/template/defaulttags.py", line 962, in do_if
    nodelist = parser.parse(("elif", "else", "endif"))
               ^^^^^^^^^^^^^^^^^^^^^^^^^^^^^^^^^^^^^^^
  File "/home/kali/CyberTea App/cyberteaenv/lib/python3.11/site-packages/django/template/base.py", line 518, in parse
    raise self.error(token, e)
  File "/home/kali/CyberTea App/cyberteaenv/lib/python3.11/site-packages/django/template/base.py", line 516, in parse
    compiled_result = compile_func(self, token)
                      ^^^^^^^^^^^^^^^^^^^^^^^^^
  File "/home/kali/CyberTea App/cyberteaenv/lib/python3.11/site-packages/django/template/defaulttags.py", line 862, in do_for
    nodelist_loop = parser.parse(
                    ^^^^^^^^^^^^^
  File "/home/kali/CyberTea App/cyberteaenv/lib/python3.11/site-packages/django/template/base.py", line 489, in parse
    raise self.error(token, e)
  File "/home/kali/CyberTea App/cyberteaenv/lib/python3.11/site-packages/django/template/base.py", line 487, in parse
    filter_expression = self.compile_filter(token.contents)
                        ^^^^^^^^^^^^^^^^^^^^^^^^^^^^^^^^^^^
  File "/home/kali/CyberTea App/cyberteaenv/lib/python3.11/site-packages/django/template/base.py", line 605, in compile_filter
    return FilterExpression(token, self)
           ^^^^^^^^^^^^^^^^^^^^^^^^^^^^^
  File "/home/kali/CyberTea App/cyberteaenv/lib/python3.11/site-packages/django/template/base.py", line 701, in __init__
    filter_func = parser.find_filter(filter_name)
                  ^^^^^^^^^^^^^^^^^^^^^^^^^^^^^^^
  File "/home/kali/CyberTea App/cyberteaenv/lib/python3.11/site-packages/django/template/base.py", line 611, in find_filter
    raise TemplateSyntaxError("Invalid filter: '%s'" % filter_name)
django.template.exceptions.TemplateSyntaxError: Invalid filter: 'replace'
WARNING 2025-01-05 19:06:13,833 log Not Found: /favicon.ico
ERROR 2025-01-05 19:06:27,487 log Internal Server Error: /forums/
Traceback (most recent call last):
  File "/home/kali/CyberTea App/cyberteaenv/lib/python3.11/site-packages/django/core/handlers/exception.py", line 55, in inner
    response = get_response(request)
               ^^^^^^^^^^^^^^^^^^^^^
  File "/home/kali/CyberTea App/cyberteaenv/lib/python3.11/site-packages/django/core/handlers/base.py", line 197, in _get_response
    response = wrapped_callback(request, *callback_args, **callback_kwargs)
               ^^^^^^^^^^^^^^^^^^^^^^^^^^^^^^^^^^^^^^^^^^^^^^^^^^^^^^^^^^^^
  File "/home/kali/CyberTea App/cybertea_project/cybertea_app/views.py", line 114, in forums
    return render(request, "cyberevents/forums.html", context)
           ^^^^^^^^^^^^^^^^^^^^^^^^^^^^^^^^^^^^^^^^^^^^^^^^^^^
  File "/home/kali/CyberTea App/cyberteaenv/lib/python3.11/site-packages/django/shortcuts.py", line 25, in render
    content = loader.render_to_string(template_name, context, request, using=using)
              ^^^^^^^^^^^^^^^^^^^^^^^^^^^^^^^^^^^^^^^^^^^^^^^^^^^^^^^^^^^^^^^^^^^^^
  File "/home/kali/CyberTea App/cyberteaenv/lib/python3.11/site-packages/django/template/loader.py", line 61, in render_to_string
    template = get_template(template_name, using=using)
               ^^^^^^^^^^^^^^^^^^^^^^^^^^^^^^^^^^^^^^^^
  File "/home/kali/CyberTea App/cyberteaenv/lib/python3.11/site-packages/django/template/loader.py", line 15, in get_template
    return engine.get_template(template_name)
           ^^^^^^^^^^^^^^^^^^^^^^^^^^^^^^^^^^
  File "/home/kali/CyberTea App/cyberteaenv/lib/python3.11/site-packages/django/template/backends/django.py", line 79, in get_template
    return Template(self.engine.get_template(template_name), self)
                    ^^^^^^^^^^^^^^^^^^^^^^^^^^^^^^^^^^^^^^^
  File "/home/kali/CyberTea App/cyberteaenv/lib/python3.11/site-packages/django/template/engine.py", line 177, in get_template
    template, origin = self.find_template(template_name)
                       ^^^^^^^^^^^^^^^^^^^^^^^^^^^^^^^^^
  File "/home/kali/CyberTea App/cyberteaenv/lib/python3.11/site-packages/django/template/engine.py", line 159, in find_template
    template = loader.get_template(name, skip=skip)
               ^^^^^^^^^^^^^^^^^^^^^^^^^^^^^^^^^^^^
  File "/home/kali/CyberTea App/cyberteaenv/lib/python3.11/site-packages/django/template/loaders/cached.py", line 57, in get_template
    template = super().get_template(template_name, skip)
               ^^^^^^^^^^^^^^^^^^^^^^^^^^^^^^^^^^^^^^^^^
  File "/home/kali/CyberTea App/cyberteaenv/lib/python3.11/site-packages/django/template/loaders/base.py", line 28, in get_template
    return Template(
           ^^^^^^^^^
  File "/home/kali/CyberTea App/cyberteaenv/lib/python3.11/site-packages/django/template/base.py", line 154, in __init__
    self.nodelist = self.compile_nodelist()
                    ^^^^^^^^^^^^^^^^^^^^^^^
  File "/home/kali/CyberTea App/cyberteaenv/lib/python3.11/site-packages/django/template/base.py", line 196, in compile_nodelist
    nodelist = parser.parse()
               ^^^^^^^^^^^^^^
  File "/home/kali/CyberTea App/cyberteaenv/lib/python3.11/site-packages/django/template/base.py", line 518, in parse
    raise self.error(token, e)
  File "/home/kali/CyberTea App/cyberteaenv/lib/python3.11/site-packages/django/template/base.py", line 516, in parse
    compiled_result = compile_func(self, token)
                      ^^^^^^^^^^^^^^^^^^^^^^^^^
  File "/home/kali/CyberTea App/cyberteaenv/lib/python3.11/site-packages/django/template/loader_tags.py", line 295, in do_extends
    nodelist = parser.parse()
               ^^^^^^^^^^^^^^
  File "/home/kali/CyberTea App/cyberteaenv/lib/python3.11/site-packages/django/template/base.py", line 518, in parse
    raise self.error(token, e)
  File "/home/kali/CyberTea App/cyberteaenv/lib/python3.11/site-packages/django/template/base.py", line 516, in parse
    compiled_result = compile_func(self, token)
                      ^^^^^^^^^^^^^^^^^^^^^^^^^
  File "/home/kali/CyberTea App/cyberteaenv/lib/python3.11/site-packages/django/template/loader_tags.py", line 234, in do_block
    nodelist = parser.parse(("endblock",))
               ^^^^^^^^^^^^^^^^^^^^^^^^^^^
  File "/home/kali/CyberTea App/cyberteaenv/lib/python3.11/site-packages/django/template/base.py", line 518, in parse
    raise self.error(token, e)
  File "/home/kali/CyberTea App/cyberteaenv/lib/python3.11/site-packages/django/template/base.py", line 516, in parse
    compiled_result = compile_func(self, token)
                      ^^^^^^^^^^^^^^^^^^^^^^^^^
  File "/home/kali/CyberTea App/cyberteaenv/lib/python3.11/site-packages/django/template/defaulttags.py", line 962, in do_if
    nodelist = parser.parse(("elif", "else", "endif"))
               ^^^^^^^^^^^^^^^^^^^^^^^^^^^^^^^^^^^^^^^
  File "/home/kali/CyberTea App/cyberteaenv/lib/python3.11/site-packages/django/template/base.py", line 518, in parse
    raise self.error(token, e)
  File "/home/kali/CyberTea App/cyberteaenv/lib/python3.11/site-packages/django/template/base.py", line 516, in parse
    compiled_result = compile_func(self, token)
                      ^^^^^^^^^^^^^^^^^^^^^^^^^
  File "/home/kali/CyberTea App/cyberteaenv/lib/python3.11/site-packages/django/template/defaulttags.py", line 862, in do_for
    nodelist_loop = parser.parse(
                    ^^^^^^^^^^^^^
  File "/home/kali/CyberTea App/cyberteaenv/lib/python3.11/site-packages/django/template/base.py", line 489, in parse
    raise self.error(token, e)
  File "/home/kali/CyberTea App/cyberteaenv/lib/python3.11/site-packages/django/template/base.py", line 487, in parse
    filter_expression = self.compile_filter(token.contents)
                        ^^^^^^^^^^^^^^^^^^^^^^^^^^^^^^^^^^^
  File "/home/kali/CyberTea App/cyberteaenv/lib/python3.11/site-packages/django/template/base.py", line 605, in compile_filter
    return FilterExpression(token, self)
           ^^^^^^^^^^^^^^^^^^^^^^^^^^^^^
  File "/home/kali/CyberTea App/cyberteaenv/lib/python3.11/site-packages/django/template/base.py", line 701, in __init__
    filter_func = parser.find_filter(filter_name)
                  ^^^^^^^^^^^^^^^^^^^^^^^^^^^^^^^
  File "/home/kali/CyberTea App/cyberteaenv/lib/python3.11/site-packages/django/template/base.py", line 611, in find_filter
    raise TemplateSyntaxError("Invalid filter: '%s'" % filter_name)
django.template.exceptions.TemplateSyntaxError: Invalid filter: 'replace'
ERROR 2025-01-05 19:07:43,957 log Internal Server Error: /search/
Traceback (most recent call last):
  File "/home/kali/CyberTea App/cyberteaenv/lib/python3.11/site-packages/django/core/handlers/exception.py", line 55, in inner
    response = get_response(request)
               ^^^^^^^^^^^^^^^^^^^^^
  File "/home/kali/CyberTea App/cyberteaenv/lib/python3.11/site-packages/django/core/handlers/base.py", line 197, in _get_response
    response = wrapped_callback(request, *callback_args, **callback_kwargs)
               ^^^^^^^^^^^^^^^^^^^^^^^^^^^^^^^^^^^^^^^^^^^^^^^^^^^^^^^^^^^^
  File "/home/kali/CyberTea App/cybertea_project/cybertea_app/views.py", line 188, in forum_search
    post.content = re.sub(r"&nbsp;", " ", post.content)
                   ^^
NameError: name 're' is not defined
WARNING 2025-01-05 19:31:38,998 log Not Found: /favicon.ico
WARNING 2025-01-05 19:40:26,283 log Not Found: /favicon.ico
WARNING 2025-01-05 19:40:34,921 log Not Found: /favicon.ico
WARNING 2025-01-05 19:45:37,070 log Not Found: /favicon.ico
WARNING 2025-01-05 19:45:41,190 log Not Found: /favicon.ico
WARNING 2025-01-05 19:45:51,083 log Not Found: /favicon.ico
WARNING 2025-01-05 20:03:40,135 log Not Found: /favicon.ico
WARNING 2025-01-05 20:07:44,034 log Not Found: /favicon.ico
WARNING 2025-01-05 20:16:04,632 log Not Found: /favicon.ico
WARNING 2025-01-05 20:24:55,759 log Not Found: /favicon.ico
WARNING 2025-01-05 20:27:40,619 log Not Found: /favicon.ico
WARNING 2025-01-05 20:28:31,493 log Not Found: /favicon.ico
WARNING 2025-01-05 20:30:56,695 log Not Found: /favicon.ico
ERROR 2025-01-05 20:33:41,407 log Internal Server Error: /create_post/
Traceback (most recent call last):
  File "/home/kali/CyberTea App/cyberteaenv/lib/python3.11/site-packages/django/core/handlers/exception.py", line 55, in inner
    response = get_response(request)
               ^^^^^^^^^^^^^^^^^^^^^
  File "/home/kali/CyberTea App/cyberteaenv/lib/python3.11/site-packages/django/core/handlers/base.py", line 197, in _get_response
    response = wrapped_callback(request, *callback_args, **callback_kwargs)
               ^^^^^^^^^^^^^^^^^^^^^^^^^^^^^^^^^^^^^^^^^^^^^^^^^^^^^^^^^^^^
  File "/home/kali/CyberTea App/cybertea_project/cybertea_app/views.py", line 143, in create_post
    author = Author.objects.get(user=request.user)
             ^^^^^^^^^^^^^^^^^^^^^^^^^^^^^^^^^^^^^
  File "/home/kali/CyberTea App/cyberteaenv/lib/python3.11/site-packages/django/db/models/manager.py", line 87, in manager_method
    return getattr(self.get_queryset(), name)(*args, **kwargs)
           ^^^^^^^^^^^^^^^^^^^^^^^^^^^^^^^^^^^^^^^^^^^^^^^^^^^
  File "/home/kali/CyberTea App/cyberteaenv/lib/python3.11/site-packages/django/db/models/query.py", line 649, in get
    raise self.model.DoesNotExist(
cybertea_app.models.Author.DoesNotExist: Author matching query does not exist.
WARNING 2025-01-05 20:34:25,359 log Not Found: /favicon.ico
WARNING 2025-01-05 20:36:34,431 log Not Found: /favicon.ico
WARNING 2025-01-05 20:36:39,728 log Forbidden (CSRF token from POST incorrect.): /create_post/
WARNING 2025-01-05 20:59:10,261 log Not Found: /favicon.ico
WARNING 2025-01-05 20:59:50,420 log Not Found: /favicon.ico
WARNING 2025-01-05 21:01:30,623 log Not Found: /favicon.ico
WARNING 2025-01-05 21:04:20,138 log Not Found: /favicon.ico
WARNING 2025-01-05 21:05:45,177 log Not Found: /favicon.ico
WARNING 2025-01-05 23:28:15,373 log Not Found: /favicon.ico
WARNING 2025-01-05 23:31:15,587 log Not Found: /favicon.ico
WARNING 2025-01-05 23:32:37,234 log Not Found: /favicon.ico
WARNING 2025-01-05 23:33:24,174 log Not Found: /favicon.ico
WARNING 2025-01-05 23:36:48,446 log Not Found: /favicon.ico
ERROR 2025-01-05 23:36:54,367 forms Failed to send password reset email to 6
Traceback (most recent call last):
  File "/home/kali/CyberTea App/cyberteaenv/lib/python3.11/site-packages/django/contrib/auth/forms.py", line 424, in send_mail
    email_message.send()
  File "/home/kali/CyberTea App/cyberteaenv/lib/python3.11/site-packages/django/core/mail/message.py", line 301, in send
    return self.get_connection(fail_silently).send_messages([self])
           ^^^^^^^^^^^^^^^^^^^^^^^^^^^^^^^^^^^^^^^^^^^^^^^^^^^^^^^^
  File "/home/kali/CyberTea App/cyberteaenv/lib/python3.11/site-packages/django/core/mail/backends/smtp.py", line 128, in send_messages
    new_conn_created = self.open()
                       ^^^^^^^^^^^
  File "/home/kali/CyberTea App/cyberteaenv/lib/python3.11/site-packages/django/core/mail/backends/smtp.py", line 95, in open
    self.connection.login(self.username, self.password)
  File "/usr/lib/python3.11/smtplib.py", line 750, in login
    raise last_exception
  File "/usr/lib/python3.11/smtplib.py", line 739, in login
    (code, resp) = self.auth(
                   ^^^^^^^^^^
  File "/usr/lib/python3.11/smtplib.py", line 662, in auth
    raise SMTPAuthenticationError(code, resp)
smtplib.SMTPAuthenticationError: (535, b'5.7.8 Username and Password not accepted. For more information, go to\n5.7.8  https://support.google.com/mail/?p=BadCredentials a640c23a62f3a-aac0f06dc7esm2181979666b.193 - gsmtp')
WARNING 2025-01-05 23:45:54,525 log Not Found: /favicon.ico
ERROR 2025-01-05 23:46:32,338 forms Failed to send password reset email to 6
Traceback (most recent call last):
  File "/home/kali/CyberTea App/cyberteaenv/lib/python3.11/site-packages/django/contrib/auth/forms.py", line 424, in send_mail
    email_message.send()
  File "/home/kali/CyberTea App/cyberteaenv/lib/python3.11/site-packages/django/core/mail/message.py", line 301, in send
    return self.get_connection(fail_silently).send_messages([self])
           ^^^^^^^^^^^^^^^^^^^^^^^^^^^^^^^^^^^^^^^^^^^^^^^^^^^^^^^^
  File "/home/kali/CyberTea App/cyberteaenv/lib/python3.11/site-packages/django/core/mail/backends/smtp.py", line 128, in send_messages
    new_conn_created = self.open()
                       ^^^^^^^^^^^
  File "/home/kali/CyberTea App/cyberteaenv/lib/python3.11/site-packages/django/core/mail/backends/smtp.py", line 95, in open
    self.connection.login(self.username, self.password)
  File "/usr/lib/python3.11/smtplib.py", line 750, in login
    raise last_exception
  File "/usr/lib/python3.11/smtplib.py", line 739, in login
    (code, resp) = self.auth(
                   ^^^^^^^^^^
  File "/usr/lib/python3.11/smtplib.py", line 662, in auth
    raise SMTPAuthenticationError(code, resp)
smtplib.SMTPAuthenticationError: (535, b'5.7.8 Username and Password not accepted. For more information, go to\n5.7.8  https://support.google.com/mail/?p=BadCredentials a640c23a62f3a-aac0efe41a6sm2209176466b.102 - gsmtp')
ERROR 2025-01-05 23:47:19,964 forms Failed to send password reset email to 6
Traceback (most recent call last):
  File "/home/kali/CyberTea App/cyberteaenv/lib/python3.11/site-packages/django/contrib/auth/forms.py", line 424, in send_mail
    email_message.send()
  File "/home/kali/CyberTea App/cyberteaenv/lib/python3.11/site-packages/django/core/mail/message.py", line 301, in send
    return self.get_connection(fail_silently).send_messages([self])
           ^^^^^^^^^^^^^^^^^^^^^^^^^^^^^^^^^^^^^^^^^^^^^^^^^^^^^^^^
  File "/home/kali/CyberTea App/cyberteaenv/lib/python3.11/site-packages/django/core/mail/backends/smtp.py", line 128, in send_messages
    new_conn_created = self.open()
                       ^^^^^^^^^^^
  File "/home/kali/CyberTea App/cyberteaenv/lib/python3.11/site-packages/django/core/mail/backends/smtp.py", line 95, in open
    self.connection.login(self.username, self.password)
  File "/usr/lib/python3.11/smtplib.py", line 750, in login
    raise last_exception
  File "/usr/lib/python3.11/smtplib.py", line 739, in login
    (code, resp) = self.auth(
                   ^^^^^^^^^^
  File "/usr/lib/python3.11/smtplib.py", line 662, in auth
    raise SMTPAuthenticationError(code, resp)
smtplib.SMTPAuthenticationError: (534, b'5.7.9 Application-specific password required. For more information, go to\n5.7.9  https://support.google.com/mail/?p=InvalidSecondFactor 4fb4d7f45d1cf-5d80675a72asm22185718a12.8 - gsmtp')
ERROR 2025-01-05 23:49:34,230 forms Failed to send password reset email to 6
Traceback (most recent call last):
  File "/home/kali/CyberTea App/cyberteaenv/lib/python3.11/site-packages/django/contrib/auth/forms.py", line 424, in send_mail
    email_message.send()
  File "/home/kali/CyberTea App/cyberteaenv/lib/python3.11/site-packages/django/core/mail/message.py", line 301, in send
    return self.get_connection(fail_silently).send_messages([self])
           ^^^^^^^^^^^^^^^^^^^^^^^^^^^^^^^^^^^^^^^^^^^^^^^^^^^^^^^^
  File "/home/kali/CyberTea App/cyberteaenv/lib/python3.11/site-packages/django/core/mail/backends/smtp.py", line 128, in send_messages
    new_conn_created = self.open()
                       ^^^^^^^^^^^
  File "/home/kali/CyberTea App/cyberteaenv/lib/python3.11/site-packages/django/core/mail/backends/smtp.py", line 95, in open
    self.connection.login(self.username, self.password)
  File "/usr/lib/python3.11/smtplib.py", line 750, in login
    raise last_exception
  File "/usr/lib/python3.11/smtplib.py", line 739, in login
    (code, resp) = self.auth(
                   ^^^^^^^^^^
  File "/usr/lib/python3.11/smtplib.py", line 662, in auth
    raise SMTPAuthenticationError(code, resp)
smtplib.SMTPAuthenticationError: (534, b'5.7.9 Application-specific password required. For more information, go to\n5.7.9  https://support.google.com/mail/?p=InvalidSecondFactor a640c23a62f3a-aac0f0652a7sm2182857466b.174 - gsmtp')
ERROR 2025-01-05 23:50:51,417 forms Failed to send password reset email to 6
Traceback (most recent call last):
  File "/home/kali/CyberTea App/cyberteaenv/lib/python3.11/site-packages/django/contrib/auth/forms.py", line 424, in send_mail
    email_message.send()
  File "/home/kali/CyberTea App/cyberteaenv/lib/python3.11/site-packages/django/core/mail/message.py", line 301, in send
    return self.get_connection(fail_silently).send_messages([self])
           ^^^^^^^^^^^^^^^^^^^^^^^^^^^^^^^^^^^^^^^^^^^^^^^^^^^^^^^^
  File "/home/kali/CyberTea App/cyberteaenv/lib/python3.11/site-packages/django/core/mail/backends/smtp.py", line 128, in send_messages
    new_conn_created = self.open()
                       ^^^^^^^^^^^
  File "/home/kali/CyberTea App/cyberteaenv/lib/python3.11/site-packages/django/core/mail/backends/smtp.py", line 95, in open
    self.connection.login(self.username, self.password)
  File "/usr/lib/python3.11/smtplib.py", line 750, in login
    raise last_exception
  File "/usr/lib/python3.11/smtplib.py", line 739, in login
    (code, resp) = self.auth(
                   ^^^^^^^^^^
  File "/usr/lib/python3.11/smtplib.py", line 662, in auth
    raise SMTPAuthenticationError(code, resp)
smtplib.SMTPAuthenticationError: (535, b'5.7.8 Username and Password not accepted. For more information, go to\n5.7.8  https://support.google.com/mail/?p=BadCredentials a640c23a62f3a-aac0f01608fsm2169346666b.150 - gsmtp')
WARNING 2025-01-05 23:52:42,085 log Not Found: /favicon.ico
ERROR 2025-01-05 23:52:43,961 forms Failed to send password reset email to 6
Traceback (most recent call last):
  File "/home/kali/CyberTea App/cyberteaenv/lib/python3.11/site-packages/django/contrib/auth/forms.py", line 424, in send_mail
    email_message.send()
  File "/home/kali/CyberTea App/cyberteaenv/lib/python3.11/site-packages/django/core/mail/message.py", line 301, in send
    return self.get_connection(fail_silently).send_messages([self])
           ^^^^^^^^^^^^^^^^^^^^^^^^^^^^^^^^^^^^^^^^^^^^^^^^^^^^^^^^
  File "/home/kali/CyberTea App/cyberteaenv/lib/python3.11/site-packages/django/core/mail/backends/smtp.py", line 128, in send_messages
    new_conn_created = self.open()
                       ^^^^^^^^^^^
  File "/home/kali/CyberTea App/cyberteaenv/lib/python3.11/site-packages/django/core/mail/backends/smtp.py", line 95, in open
    self.connection.login(self.username, self.password)
  File "/usr/lib/python3.11/smtplib.py", line 750, in login
    raise last_exception
  File "/usr/lib/python3.11/smtplib.py", line 739, in login
    (code, resp) = self.auth(
                   ^^^^^^^^^^
  File "/usr/lib/python3.11/smtplib.py", line 662, in auth
    raise SMTPAuthenticationError(code, resp)
smtplib.SMTPAuthenticationError: (534, b'5.7.9 Application-specific password required. For more information, go to\n5.7.9  https://support.google.com/mail/?p=InvalidSecondFactor a640c23a62f3a-aac0f06c654sm2203191166b.185 - gsmtp')
ERROR 2025-01-05 23:57:43,420 forms Failed to send password reset email to 6
Traceback (most recent call last):
  File "/home/kali/CyberTea App/cyberteaenv/lib/python3.11/site-packages/django/contrib/auth/forms.py", line 424, in send_mail
    email_message.send()
  File "/home/kali/CyberTea App/cyberteaenv/lib/python3.11/site-packages/django/core/mail/message.py", line 301, in send
    return self.get_connection(fail_silently).send_messages([self])
           ^^^^^^^^^^^^^^^^^^^^^^^^^^^^^^^^^^^^^^^^^^^^^^^^^^^^^^^^
  File "/home/kali/CyberTea App/cyberteaenv/lib/python3.11/site-packages/django/core/mail/backends/smtp.py", line 128, in send_messages
    new_conn_created = self.open()
                       ^^^^^^^^^^^
  File "/home/kali/CyberTea App/cyberteaenv/lib/python3.11/site-packages/django/core/mail/backends/smtp.py", line 95, in open
    self.connection.login(self.username, self.password)
  File "/usr/lib/python3.11/smtplib.py", line 750, in login
    raise last_exception
  File "/usr/lib/python3.11/smtplib.py", line 739, in login
    (code, resp) = self.auth(
                   ^^^^^^^^^^
  File "/usr/lib/python3.11/smtplib.py", line 662, in auth
    raise SMTPAuthenticationError(code, resp)
smtplib.SMTPAuthenticationError: (534, b'5.7.9 Application-specific password required. For more information, go to\n5.7.9  https://support.google.com/mail/?p=InvalidSecondFactor a640c23a62f3a-aac0f013946sm2200414666b.136 - gsmtp')
ERROR 2025-01-05 23:58:45,437 forms Failed to send password reset email to 6
Traceback (most recent call last):
  File "/home/kali/CyberTea App/cyberteaenv/lib/python3.11/site-packages/django/contrib/auth/forms.py", line 424, in send_mail
    email_message.send()
  File "/home/kali/CyberTea App/cyberteaenv/lib/python3.11/site-packages/django/core/mail/message.py", line 301, in send
    return self.get_connection(fail_silently).send_messages([self])
           ^^^^^^^^^^^^^^^^^^^^^^^^^^^^^^^^^^^^^^^^^^^^^^^^^^^^^^^^
  File "/home/kali/CyberTea App/cyberteaenv/lib/python3.11/site-packages/django/core/mail/backends/smtp.py", line 128, in send_messages
    new_conn_created = self.open()
                       ^^^^^^^^^^^
  File "/home/kali/CyberTea App/cyberteaenv/lib/python3.11/site-packages/django/core/mail/backends/smtp.py", line 95, in open
    self.connection.login(self.username, self.password)
  File "/usr/lib/python3.11/smtplib.py", line 750, in login
    raise last_exception
  File "/usr/lib/python3.11/smtplib.py", line 739, in login
    (code, resp) = self.auth(
                   ^^^^^^^^^^
  File "/usr/lib/python3.11/smtplib.py", line 662, in auth
    raise SMTPAuthenticationError(code, resp)
smtplib.SMTPAuthenticationError: (535, b'5.7.8 Username and Password not accepted. For more information, go to\n5.7.8  https://support.google.com/mail/?p=BadCredentials 4fb4d7f45d1cf-5d80675ab3bsm22351844a12.5 - gsmtp')
WARNING 2025-01-06 00:00:50,401 log Not Found: /favicon.ico
WARNING 2025-01-06 00:01:49,497 log Forbidden (CSRF token from POST incorrect.): /password_reset/
ERROR 2025-01-06 00:02:03,176 forms Failed to send password reset email to 6
Traceback (most recent call last):
  File "/home/kali/CyberTea App/cyberteaenv/lib/python3.11/site-packages/django/contrib/auth/forms.py", line 424, in send_mail
    email_message.send()
  File "/home/kali/CyberTea App/cyberteaenv/lib/python3.11/site-packages/django/core/mail/message.py", line 301, in send
    return self.get_connection(fail_silently).send_messages([self])
           ^^^^^^^^^^^^^^^^^^^^^^^^^^^^^^^^^^^^^^^^^^^^^^^^^^^^^^^^
  File "/home/kali/CyberTea App/cyberteaenv/lib/python3.11/site-packages/django/core/mail/backends/smtp.py", line 128, in send_messages
    new_conn_created = self.open()
                       ^^^^^^^^^^^
  File "/home/kali/CyberTea App/cyberteaenv/lib/python3.11/site-packages/django/core/mail/backends/smtp.py", line 95, in open
    self.connection.login(self.username, self.password)
  File "/usr/lib/python3.11/smtplib.py", line 750, in login
    raise last_exception
  File "/usr/lib/python3.11/smtplib.py", line 739, in login
    (code, resp) = self.auth(
                   ^^^^^^^^^^
  File "/usr/lib/python3.11/smtplib.py", line 662, in auth
    raise SMTPAuthenticationError(code, resp)
smtplib.SMTPAuthenticationError: (534, b'5.7.9 Application-specific password required. For more information, go to\n5.7.9  https://support.google.com/mail/?p=InvalidSecondFactor a640c23a62f3a-aac0efe41f0sm2160549166b.114 - gsmtp')
ERROR 2025-01-06 00:09:18,078 forms Failed to send password reset email to 6
Traceback (most recent call last):
  File "/home/kali/CyberTea App/cyberteaenv/lib/python3.11/site-packages/django/contrib/auth/forms.py", line 424, in send_mail
    email_message.send()
  File "/home/kali/CyberTea App/cyberteaenv/lib/python3.11/site-packages/django/core/mail/message.py", line 301, in send
    return self.get_connection(fail_silently).send_messages([self])
           ^^^^^^^^^^^^^^^^^^^^^^^^^^^^^^^^^^^^^^^^^^^^^^^^^^^^^^^^
  File "/home/kali/CyberTea App/cyberteaenv/lib/python3.11/site-packages/django/core/mail/backends/smtp.py", line 128, in send_messages
    new_conn_created = self.open()
                       ^^^^^^^^^^^
  File "/home/kali/CyberTea App/cyberteaenv/lib/python3.11/site-packages/django/core/mail/backends/smtp.py", line 95, in open
    self.connection.login(self.username, self.password)
  File "/usr/lib/python3.11/smtplib.py", line 750, in login
    raise last_exception
  File "/usr/lib/python3.11/smtplib.py", line 739, in login
    (code, resp) = self.auth(
                   ^^^^^^^^^^
  File "/usr/lib/python3.11/smtplib.py", line 662, in auth
    raise SMTPAuthenticationError(code, resp)
smtplib.SMTPAuthenticationError: (535, b'5.7.8 Username and Password not accepted. For more information, go to\n5.7.8  https://support.google.com/mail/?p=BadCredentials a640c23a62f3a-aac0e82f178sm2165997466b.38 - gsmtp')
ERROR 2025-01-06 00:13:02,850 forms Failed to send password reset email to 6
Traceback (most recent call last):
  File "/home/kali/CyberTea App/cyberteaenv/lib/python3.11/site-packages/django/contrib/auth/forms.py", line 424, in send_mail
    email_message.send()
  File "/home/kali/CyberTea App/cyberteaenv/lib/python3.11/site-packages/django/core/mail/message.py", line 301, in send
    return self.get_connection(fail_silently).send_messages([self])
           ^^^^^^^^^^^^^^^^^^^^^^^^^^^^^^^^^^^^^^^^^^^^^^^^^^^^^^^^
  File "/home/kali/CyberTea App/cyberteaenv/lib/python3.11/site-packages/django/core/mail/backends/smtp.py", line 128, in send_messages
    new_conn_created = self.open()
                       ^^^^^^^^^^^
  File "/home/kali/CyberTea App/cyberteaenv/lib/python3.11/site-packages/django/core/mail/backends/smtp.py", line 95, in open
    self.connection.login(self.username, self.password)
  File "/usr/lib/python3.11/smtplib.py", line 750, in login
    raise last_exception
  File "/usr/lib/python3.11/smtplib.py", line 739, in login
    (code, resp) = self.auth(
                   ^^^^^^^^^^
  File "/usr/lib/python3.11/smtplib.py", line 662, in auth
    raise SMTPAuthenticationError(code, resp)
smtplib.SMTPAuthenticationError: (535, b'5.7.8 Username and Password not accepted. For more information, go to\n5.7.8  https://support.google.com/mail/?p=BadCredentials 4fb4d7f45d1cf-5d80679f0e4sm22323370a12.42 - gsmtp')
ERROR 2025-01-06 00:14:42,491 forms Failed to send password reset email to 6
Traceback (most recent call last):
  File "/home/kali/CyberTea App/cyberteaenv/lib/python3.11/site-packages/django/contrib/auth/forms.py", line 424, in send_mail
    email_message.send()
  File "/home/kali/CyberTea App/cyberteaenv/lib/python3.11/site-packages/django/core/mail/message.py", line 301, in send
    return self.get_connection(fail_silently).send_messages([self])
           ^^^^^^^^^^^^^^^^^^^^^^^^^^^^^^^^^^^^^^^^^^^^^^^^^^^^^^^^
  File "/home/kali/CyberTea App/cyberteaenv/lib/python3.11/site-packages/django/core/mail/backends/smtp.py", line 128, in send_messages
    new_conn_created = self.open()
                       ^^^^^^^^^^^
  File "/home/kali/CyberTea App/cyberteaenv/lib/python3.11/site-packages/django/core/mail/backends/smtp.py", line 95, in open
    self.connection.login(self.username, self.password)
  File "/usr/lib/python3.11/smtplib.py", line 750, in login
    raise last_exception
  File "/usr/lib/python3.11/smtplib.py", line 739, in login
    (code, resp) = self.auth(
                   ^^^^^^^^^^
  File "/usr/lib/python3.11/smtplib.py", line 662, in auth
    raise SMTPAuthenticationError(code, resp)
smtplib.SMTPAuthenticationError: (535, b'5.7.8 Username and Password not accepted. For more information, go to\n5.7.8  https://support.google.com/mail/?p=BadCredentials a640c23a62f3a-aac0e82f621sm2176655066b.40 - gsmtp')
WARNING 2025-01-06 00:20:15,543 log Not Found: /favicon.ico
WARNING 2025-01-06 14:11:51,491 log Not Found: /favicon.ico
WARNING 2025-01-06 14:20:16,593 log Not Found: /favicon.ico
WARNING 2025-01-06 14:22:07,662 log Not Found: /favicon.ico
WARNING 2025-01-06 14:26:56,570 log Not Found: /favicon.ico
ERROR 2025-01-06 14:30:04,846 log Internal Server Error: /create_post/
Traceback (most recent call last):
  File "/home/kali/CyberTea App/cyberteaenv/lib/python3.11/site-packages/django/core/handlers/exception.py", line 55, in inner
    response = get_response(request)
               ^^^^^^^^^^^^^^^^^^^^^
  File "/home/kali/CyberTea App/cyberteaenv/lib/python3.11/site-packages/django/core/handlers/base.py", line 197, in _get_response
    response = wrapped_callback(request, *callback_args, **callback_kwargs)
               ^^^^^^^^^^^^^^^^^^^^^^^^^^^^^^^^^^^^^^^^^^^^^^^^^^^^^^^^^^^^
  File "/home/kali/CyberTea App/cybertea_project/cybertea_app/views.py", line 143, in create_post
    author = Author.objects.get(user=request.user)
             ^^^^^^^^^^^^^^^^^^^^^^^^^^^^^^^^^^^^^
  File "/home/kali/CyberTea App/cyberteaenv/lib/python3.11/site-packages/django/db/models/manager.py", line 87, in manager_method
    return getattr(self.get_queryset(), name)(*args, **kwargs)
           ^^^^^^^^^^^^^^^^^^^^^^^^^^^^^^^^^^^^^^^^^^^^^^^^^^^
  File "/home/kali/CyberTea App/cyberteaenv/lib/python3.11/site-packages/django/db/models/query.py", line 649, in get
    raise self.model.DoesNotExist(
cybertea_app.models.Author.DoesNotExist: Author matching query does not exist.
WARNING 2025-01-06 14:30:31,918 log Not Found: /favicon.ico
WARNING 2025-01-06 14:30:46,051 log Not Found: /favicon.ico
WARNING 2025-01-06 14:32:40,490 log Not Found: /favicon.ico
WARNING 2025-01-06 14:34:21,718 log Not Found: /favicon.ico
WARNING 2025-01-06 14:34:24,908 log Forbidden (CSRF token from POST incorrect.): /create_post/
WARNING 2025-01-06 14:34:25,040 log Not Found: /favicon.ico
WARNING 2025-01-06 14:41:53,971 log Not Found: /favicon.ico
